package learncoroutine

import kotlinx.coroutines.*
import java.io.IOException

/**
 * Crete by dumingwei on 2019-07-22
 * Desc: 异常处理与监督
 *
 */
private fun main1() = runBlocking {
    val job = GlobalScope.launch {
        println("Throwing exception from launch")
        throw IndexOutOfBoundsException() // Will be printed to the console by Thread.defaultUncaughtExceptionHandler
    }
    job.join()
    println("Joined failed job")
    val deferred = GlobalScope.async {
        println("Throwing exception from async")
        throw ArithmeticException() // Nothing is printed, relying on user to call await
    }
    try {
        deferred.await()
        println("Unreached")
    } catch (e: ArithmeticException) {
        println("Caught ArithmeticException")
    }
}

private fun main2() = runBlocking {
    val handler = CoroutineExceptionHandler { _, exception ->
        println("Caught $exception")
    }
    val job = GlobalScope.launch(handler) {
        throw AssertionError()
    }
    val deferred = GlobalScope.async(handler) {
        //不会抛出异常，除非用户调用await()
        throw ArithmeticException() // Nothing will be printed, relying on user to call deferred.await()
    }
    joinAll(job, deferred)
}

private fun mai3() = runBlocking {
    val job = launch {
        val child = launch {
            try {
                delay(Long.MAX_VALUE)
            } finally {
                println("Child is cancelled")
            }
        }
        yield()
        println("Cancelling child")
        child.cancel()
        child.join()
        yield()
        println("Parent is not cancelled")
    }
    job.join()
}

/**
 * 如果协程遇到了除了CancellationException之外的异常，那么协程会被取消。
 * 父协程会等待所有的子协程结束后处理该异常。
 */
private fun main4() = runBlocking {
    //sampleStart
    val handler = CoroutineExceptionHandler { _, exception ->
        println("Caught $exception")
    }
    val job = GlobalScope.launch(handler) {
        launch {
            // the first child
            try {
                delay(Long.MAX_VALUE)
            } finally {
                withContext(NonCancellable) {
                    println("Children are cancelled, but exception is not handled until all children terminate")
                    delay(100)
                    println("The first child finished its non cancellable block")
                }
            }
        }
        launch {
            // the second child
            delay(10)
            println("Second child throws an exception")
            throw ArithmeticException()
        }
    }
    job.join()
}

/**
 * 异常聚合
 */
private fun main5() = runBlocking {
    val handler = CoroutineExceptionHandler { _, exception ->
        println("Caught $exception with suppressed ${exception.suppressed?.contentToString()}")
    }
    val job = GlobalScope.launch(handler) {
        launch {
            try {
                delay(Long.MAX_VALUE)
            } finally {
                throw ArithmeticException()
            }
        }
        launch {
            delay(100)
            throw IOException()
        }
        delay(Long.MAX_VALUE)
    }
    job.join()
}

/**
 * 监督任务
 */
private fun main6() = runBlocking {
    val supervisor = SupervisorJob()
    with(CoroutineScope(coroutineContext + supervisor)) {
        // launch the first child -- its exception is ignored for this example (don't do this in practice!)
        val firstChild = launch(CoroutineExceptionHandler { _, _ -> }) {
            println("First child is failing")
            throw AssertionError("First child is cancelled")
        }
        // launch the second child
        val secondChild = launch {
            firstChild.join()
            // Cancellation of the first child is not propagated to the second child
            println("First child is cancelled: ${firstChild.isCancelled}, but second one is still active")
            try {
                delay(Long.MAX_VALUE)
            } finally {
                // But cancellation of the supervisor is propagated
                println("Second child is cancelled because supervisor is cancelled")
            }
        }
        // wait until the first child fails & completes
        firstChild.join()
        println("Cancelling supervisor")
        supervisor.cancel()
        secondChild.join()
    }
}

private fun main7() = runBlocking {
    try {
        supervisorScope {
            val child = launch {
                try {
                    println("Child is sleeping")
                    delay(Long.MAX_VALUE)
                } finally {
                    println("Child is cancelled")
                }
            }
            // Give our child a chance to execute and print using yield
            yield()
            println("Throwing exception from scope")
            throw AssertionError()
        }
    } catch (e: AssertionError) {
        println("Caught assertion error")
    }
}

private fun main() = runBlocking {
    val handler = CoroutineExceptionHandler { _, exception ->
        println("Caught $exception")
    }
    supervisorScope {
        val child = launch(handler) {
            println("Child throws an exception")
            throw AssertionError()
        }
        println("Scope is completing")
    }
    println("Scope is completed")
}